<robot name="agv">


    <material name="blue">
        <color rgba="0 0 0.8 1"/>
    </material>

    <material name="black">
        <color rgba="0 0 0 1"/>
    </material>

    <material name="white">
        <color rgba="1 1 1 1"/>
    </material>

    <material name="red">
        <color rgba="0.8 0 0 1"/>
    </material>

    <material name="green">
        <color rgba="0 0.8 0 1"/>
    </material>

    <material name="gray">
        <color rgba="0.5 0.5 0.5 1"/>
    </material>

    <material name="light_gray">
        <color rgba="0.7 0.7 0.7 1"/>
    </material>

    <material name="dark_gray">
        <color rgba="0.3 0.3 0.3 1"/>
    </material>

    <material name="yellow">
        <color rgba="0.7 0.8 0 1"/>
    </material>

    <link name="base_link">
        <collision name='base_link'>
            <geometry>
                <box size="0.672 0.430 0.180"/>
            </geometry>
        </collision>
        <visual name="visual">
            <geometry>
                <mesh filename="package://agv_description/mesh/base_link.stl" scale="0.001 0.001 0.001"/>
            </geometry>
            <origin rpy="0 0 1.5707" xyz="0 0 0"/>
            <material name="gray"/>
        </visual>
        <inertial>
            <origin xyz="0 0 0" rpy="0 0 0"/>
            <mass value="40"/>
            <inertia ixx="0.1" ixy="0.001" ixz="0.001" iyy="0.1" iyz="0.001" izz="0.1"/>
        </inertial>
    </link>

    <link name="base_footprint">
        <collision name="collision">
            <geometry>
                <cylinder length="0.105" radius="0.1016"/>
            </geometry>
        </collision>
        <visual name="visual">
            <origin rpy="0 0 1.5707" xyz="0 -0.0525 0"/>
            <geometry>
                <mesh filename="package://agv_description/mesh/wheel_fl.stl"  scale="0.001 0.001 0.001"/>
            </geometry>
            <material name="yellow"/>
        </visual>
        <inertial>
            <origin xyz="0 0 0" rpy="0 0 0"/>
            <mass value="5"/>
            <inertia ixx="0.001" ixy="0.00001" ixz="0.00001" iyy="0.001" iyz="0.00001" izz="0.001"/>
        </inertial>
    </link>

    <link name="front_left_wheel">
        <collision name="collision">
            <geometry>
                <cylinder length="0.105" radius="0.1016"/>
            </geometry>
        </collision>
        <visual name="visual">
            <origin rpy="0 0 -1.5707" xyz="0 0.0525 0"/>
            <geometry>
                <mesh filename="package://agv_description/mesh/wheel_fr.stl"  scale="0.001 0.001 0.001"/>
            </geometry>
            <material name="yellow"/>
        </visual>
        <inertial>
            <origin xyz="0 0 0" rpy="0 0 0"/>
            <mass value="5"/>
            <inertia ixx="0.001" ixy="0.00001" ixz="0.00001" iyy="0.001" iyz="0.00001" izz="0.001"/>
        </inertial>
    </link>

    <link name="front_right_wheel">
        <collision name="collision">
            <geometry>
                <cylinder length="0.105" radius="0.1016"/>
            </geometry>
        </collision>
        <visual name="visual">
            <origin rpy="0 0 -1.5707" xyz="0 0.0525 0"/>
            <geometry>
                <mesh filename="package://agv_description/mesh/wheel_fr.stl" scale="0.001 0.001 0.001"/>
            </geometry>
            <material name="yellow"/>
        </visual>
        <inertial>
            <origin xyz="0 0 0" rpy="0 0 0"/>
            <mass value="5"/>
            <inertia ixx="0.001" ixy="0.00001" ixz="0.00001" iyy="0.001" iyz="0.00001" izz="0.001"/>
        </inertial>
    </link>

    <link name="back_left_wheel">
        <collision name="collision">
            <geometry>
                <cylinder length="0.105" radius="0.1016"/>
            </geometry>
        </collision>
        <visual name="visual">
            <origin rpy="0 0 -1.5707" xyz="0 0.0525 0"/>
            <geometry>
                <mesh filename="package://agv_description/mesh/wheel_fr.stl" scale="0.001 0.001 0.001"/>
            </geometry>
            <material name="yellow"/>
        </visual>
        <inertial>
            <origin xyz="0 0 0" rpy="0 0 0"/>
            <mass value="5"/>
            <inertia ixx="0.001" ixy="0.00001" ixz="0.00001" iyy="0.001" iyz="0.00001" izz="0.001"/>
        </inertial>
    </link>   
    
    <link name="back_right_wheel">
        <collision name="collision">
            <geometry>
                <cylinder length="0.105" radius="0.1016"/>
            </geometry>
        </collision>
        <visual name="visual">
            <origin rpy="0 0 1.5707" xyz="0 -0.0525 0"/>
            <geometry>
                <mesh filename="package://agv_description/mesh/wheel_fl.stl" scale="0.001 0.001 0.001"/>
            </geometry>
            <material name="yellow"/>
        </visual>
        <inertial>
            <origin xyz="0 0 0" rpy="0 0 0"/>
            <mass value="5"/>
            <inertia ixx="0.001" ixy="0.00001" ixz="0.00001" iyy="0.001" iyz="0.00001" izz="0.001"/>
        </inertial>
    </link>

    <link name="imu_link"/>

    <link name="base_scan"/>

    <link name="rplidar_r">
        <collision name="collision">
            <geometry>
                <cylinder length="0.070" radius="0.025"/>
            </geometry>
        </collision>   
        <visual name="visual">
            <geometry>
                <mesh filename="package://agv_description/mesh/RPlidar.stl" scale="0.001 0.001 0.001"/>
            </geometry>
            <material name="dark_gray"/>
        </visual> 
        <inertial>
            <origin xyz="0 0 0" rpy="0 0 0"/>
            <mass value="0.1"/>
            <inertia ixx="0.0001" ixy="0.000001" ixz="0.000001" iyy="0.0001" iyz="0.000001" izz="0.001"/>
        </inertial>
    </link>

    <link name="rplidar_l">
        <collision name="collision">
            <geometry>
                <cylinder length="0.070" radius="0.025"/>
            </geometry>
        </collision>   
        <visual name="visual">
            <geometry>
                <mesh filename="package://agv_description/mesh/RPlidar.stl" scale="0.001 0.001 0.001"/>
            </geometry>
            <material name="dark_gray"/>
        </visual> 
        <inertial>
            <origin xyz="0 0 0" rpy="0 0 0"/>
            <mass value="0.1"/>
            <inertia ixx="0.0001" ixy="0.000001" ixz="0.000001" iyy="0.0001" iyz="0.000001" izz="0.001"/>
        </inertial>
    </link>

    <joint name="base_joint" type="fixed">
        <parent link="base_footprint"/>
        <child link="base_link"/>
        <origin xyz="0 0 0.1016" rpy="0 0 0"/>
    </joint>

    <joint name="fl_wheel_joint" type="continuous">
        <parent link="base_link"/>
        <child link="front_left_wheel"/>
        <origin xyz="0.2797 -0.282 0" rpy="0 0 0"/>
        <axis xyz="0 1 0"/>
    </joint>

    <joint name="fr_wheel_joint" type="continuous">
        <parent link="base_link"/>
        <child link="front_right_wheel"/>
        <origin xyz="0.2797 0.282 0" rpy="0 0 0"/>
        <axis xyz="0 1 0"/>
    </joint>

    <joint name="bl_wheel_joint" type="continuous">
        <parent link="base_link"/>
        <child link="back_left_wheel"/>
        <origin xyz="-0.2797 -0.282 0" rpy="0 0 0"/>
        <axis xyz="0 1 0"/>
    </joint>

    <joint name="br_wheel_joint" type="continuous">
        <parent link="base_link"/>
        <child link="back_right_wheel"/>
        <origin xyz="-0.2797 0.282 0" rpy="0 0 0"/>
        <axis xyz="0 1 0"/>
    </joint>

    <joint name="imu_joint" type="fixed">
        <parent link="base_link"/>
        <child link="imu_link"/>
        <origin xyz="0 0 0" rpy="0 0 0"/>
    </joint>

    <joint name="scan_joint" type="fixed">
        <parent link="base_link"/>
        <child link="base_scan"/>
        <origin xyz="0 0 0.124" rpy="0 0 0"/>
    </joint>

    <joint name="fl_lidar_joint" type="fixed">
        <parent link="base_scan"/>
        <child link="rplidar_l"/>
        <!-- <origin xyz="0.313 0.368 0" rpy="0 0 3.141592"/> -->
        <origin xyz="0.368 0.313 0" rpy="0 0 3.141592"/>
    </joint>

    <joint name="br_lidar_joint" type="fixed">
        <parent link="base_scan"/>
        <child link="rplidar_r"/>
        <origin xyz="-0.368 -0.313 0" rpy="0 0 0"/>
        <!-- <origin xyz="-0.313 -0.368 0" rpy="0 0 3.141592"/> -->
    </joint>
</robot>