<?xml version="1.0"?>
<robot name="agv_gazebo" xmlns:xacro="http://www.ros.org/wiki/xacro">
    <material name="blue">
        <color rgba="0.4 0.4 0.8 1"/>
    </material>

    <material name="black">
        <color rgba="0 0 0 1"/>
    </material>

    <material name="white">
        <color rgba="1 1 1 1"/>
    </material>

    <material name="red">
        <color rgba="0.8 0 0 1"/>
    </material>

    <material name="green">
        <color rgba="0 0.8 0 1"/>
    </material>

    <material name="gray">
        <color rgba="0.5 0.5 0.5 1"/>
    </material>

    <material name="light_gray">
        <color rgba="0.7 0.7 0.7 1"/>
    </material>

    <material name="dark_gray">
        <color rgba="0.3 0.3 0.3 1"/>
    </material>

    <material name="yellow">
        <color rgba="0.7 0.8 0 1"/>
    </material>

    <link name="base_footprint"/>

    <link name="base_link">
        
        <collision name='base_link'>
            <geometry>
                <box size="0.672 0.430 0.180"/>
            </geometry>
        </collision>
        <visual name="visual">
            <geometry>
                <mesh filename="package://agv_description/mesh/base_link.stl" scale="0.001 0.001 0.001"/>
            </geometry>
            <origin rpy="0 0 1.5707" xyz="0 0 0"/>
            <material name="blue"/>
        </visual>
        <inertial>
            <origin xyz="0 0 0" rpy="0 0 0"/>
            <mass value="80"/>
            <inertia ixx="3.76771333" ixy="5.438133333" ixz="5.438133333" iyy="4.866246667" iyz="17.15306667" izz="7.520346667"/>
        </inertial>
    </link>

    <link name="front_left_wheel">
        <collision name="collision">
            <geometry>
                <cylinder length="0.105" radius="0.1016"/>
            </geometry>
        </collision>
        <visual name="visual">
            <origin rpy="0 0 1.5707" xyz="0 -0.0525 0"/>
            <geometry>
                <mesh filename="package://agv_description/mesh/wheel_fl.stl"  scale="0.001 0.001 0.001"/>
            </geometry>
            <material name="yellow"/>
        </visual>
        <inertial>
            <origin xyz="0 0 0" rpy="0 0 0"/>
            <mass value="5"/>
            <inertia ixx="1" ixy="1" ixz="1" iyy="1" iyz="1" izz="1"/>
        </inertial>
    </link>

    <link name="front_right_wheel">
        <collision name="collision">
            <geometry>
                <cylinder length="0.105" radius="0.1016"/>
            </geometry>
        </collision>
        <visual name="visual">
            <origin rpy="0 0 -1.5707" xyz="0 0.0525 0"/>
            <geometry>
                <mesh filename="package://agv_description/mesh/wheel_fr.stl"  scale="0.001 0.001 0.001"/>
            </geometry>
            <material name="yellow"/>
        </visual>
        <inertial>
            <origin xyz="0 0 0" rpy="0 0 0"/>
            <mass value="5"/>
            <inertia ixx="1" ixy="1" ixz="1" iyy="1" iyz="1" izz="1"/>
        </inertial>
    </link>

    <link name="back_left_wheel">
        <collision name="collision">
            <geometry>
                <cylinder length="0.105" radius="0.1016"/>
            </geometry>
        </collision>
        <visual name="visual">
            <origin rpy="0 0 -1.5707" xyz="0 0.0525 0"/>
            <geometry>
                <mesh filename="package://agv_description/mesh/wheel_fr.stl" scale="0.001 0.001 0.001"/>
            </geometry>
            <material name="yellow"/>
        </visual>
        <inertial>
            <origin xyz="0 0 0" rpy="0 0 0"/>
            <mass value="5"/>
            <inertia ixx="1" ixy="1" ixz="1" iyy="1" iyz="1" izz="1"/>
        </inertial>
    </link>

    <link name="back_right_wheel">
        <collision name="collision">
            <geometry>
                <cylinder length="0.105" radius="0.1016"/>
            </geometry>
        </collision>
        <visual name="visual">
            <origin rpy="0 0 1.5707" xyz="0 -0.0525 0"/>
            <geometry>
                <mesh filename="package://agv_description/mesh/wheel_fl.stl" scale="0.001 0.001 0.001"/>
            </geometry>
            <material name="yellow"/>
        </visual>
        <inertial>
            <origin xyz="0 0 0" rpy="0 0 0"/>
            <mass value="5"/>
            <inertia ixx="1" ixy="1" ixz="1" iyy="1" iyz="1" izz="1"/>
        </inertial>
    </link>

    <link name="imu_link"/>

    <link name="base_scan"/>
    
    <link name="rplidar_r">
        <collision name="collision">
            <geometry>
                <cylinder length="0.070" radius="0.025"/>
            </geometry>
        </collision>   
        <visual name="visual">
            <geometry>
                <mesh filename="package://agv_description/mesh/RPlidar.stl" scale="0.001 0.001 0.001"/>
            </geometry>
            <material name="dark_gray"/>
        </visual> 
        <inertial>
            <origin xyz="0 0 0" rpy="0 0 0"/>
            <mass value="0.1"/>
            <inertia ixx="0.0001" ixy="0.000001" ixz="0.000001" iyy="0.0001" iyz="0.000001" izz="0.001"/>
        </inertial>
    </link>
    <link name="rplidar_l">
        <collision name="collision">
            <geometry>
                <cylinder length="0.070" radius="0.025"/>
            </geometry>
        </collision>   
        <visual name="visual">
            <geometry>
                <mesh filename="package://agv_description/mesh/RPlidar.stl" scale="0.001 0.001 0.001"/>
            </geometry>
            <material name="dark_gray"/>
        </visual> 
        <inertial>
            <origin xyz="0 0 0" rpy="0 0 0"/>
            <mass value="0.1"/>
            <inertia ixx="0.0001" ixy="0.000001" ixz="0.000001" iyy="0.0001" iyz="0.000001" izz="0.001"/>
        </inertial>
    </link>

    <joint name="base_joint" type="fixed">
        <parent link="base_footprint"/>
        <child link="base_link"/>
        <origin xyz="0 0 0.1016" rpy="0 0 0"/>
    </joint>

    <joint name="fl_wheel_joint" type="continuous">
        <parent link="base_link"/>
        <child link="front_left_wheel"/>
        <origin xyz="0.2797 -0.282 0" rpy="0 0 0"/>
        <axis xyz="0 1 0"/>
    </joint>

    <joint name="fr_wheel_joint" type="continuous">
        <parent link="base_link"/>
        <child link="front_right_wheel"/>
        <origin xyz="0.2797 0.282 0" rpy="0 0 0"/>
        <axis xyz="0 1 0"/>
    </joint>

    <joint name="bl_wheel_joint" type="continuous">
        <parent link="base_link"/>
        <child link="back_left_wheel"/>
        <origin xyz="-0.2797 -0.282 0" rpy="0 0 0"/>
        <axis xyz="0 1 0"/>
    </joint>

    <joint name="br_wheel_joint" type="continuous">
        <parent link="base_link"/>
        <child link="back_right_wheel"/>
        <origin xyz="-0.2797 0.282 0" rpy="0 0 0"/>
        <axis xyz="0 1 0"/>
    </joint>

    <joint name="imu_joint" type="fixed">
        <parent link="base_link"/>
        <child link="imu_link"/>
        <origin xyz="0 0 0" rpy="0 0 0"/>
    </joint>

    <joint name="scan_joint" type="fixed">
        <parent link="base_link"/>
        <child link="base_scan"/>
        <origin xyz="0 0 0.124" rpy="0 0 0"/>
    </joint>

    <joint name="fl_lidar_joint" type="fixed">
        <parent link="base_scan"/>
        <child link="rplidar_l"/>
        <origin xyz="0.368 0.313 0" rpy="0 0 3.141592"/>
    </joint>

    <joint name="br_lidar_joint" type="fixed">
        <parent link="base_scan"/>
        <child link="rplidar_r"/>
        <origin xyz="-0.368 -0.313 0" rpy="0 0 0"/>
    </joint>

    <gazebo reference="base_link">
        <material>Gazebo/DarkGrey</material>
    </gazebo>

    <!-- <gazebo>
        <plugin name="mecanum_drive_controller" filename="libgazebo_ros_skid_steer_drive.so">
            <updateRate>100.0</updateRate>
            <robotNamespace>/</robotNamespace>
            <odometryFrame>odom</odometryFrame>
            <odometryTopic>odom</odometryTopic>
            <publishOdomTF>true</publishOdomTF>
            <robotBaseFrame>base_footprint</robotBaseFrame>
            <publishWheelTF>false</publishWheelTF>
            <publishTf>true</publishTf>
            <publishWheelJointState>true</publishWheelJointState>
            <leftFrontJoint>fl_wheel_joint</leftFrontJoint>
            <rightFrontJoint>fr_wheel_joint</rightFrontJoint>
            <leftRearJoint>bl_wheel_joint</leftRearJoint>
            <rightRearJoint>br_wheel_joint</rightRearJoint>
            <wheelSeparation>0.5594</wheelSeparation>
            <wheelDiameter>20.32</wheelDiameter>
            <torque>10000</torque>
            <tpicName>cmd_vel</tpicName>
            <commandTopic>cmd_vel</commandTopic>
            <covariance_x>0.0001</covariance_x>
            <covariance_y>0.0001</covariance_y>
            <covariance_yaw>0.01</covariance_yaw>
            <broadcastTF>true</broadcastTF>
        </plugin>
    </gazebo> -->
    
    <!-- <gazebo>
        <plugin filename="libgazebo_force_based_move.so" name="mecanum_control">
            <commandTopic>cmd_vel</commandTopic>
            <odometryTopic>odom</odometryTopic>
            <odometryFrame>odom</odometryFrame>
            <odometryRate>50.0</odometryRate>
            <robotBaseFrame>base_footprint</robotBaseFrame>
            <cmdVelTimeOut>0.25</cmdVelTimeOut>
            <publishOdometryTf>true</publishOdometryTf>
            <publishWheelJointState>true</publishWheelJointState>
            <publishTf>true</publishTf>
            <broadcastTF>true</broadcastTF>
            <yaw_velocity_p_gain>1.0</yaw_velocity_p_gain>
            <x_velocity_p_gain>15.0</x_velocity_p_gain>
            <y_velocity_p_gain>15.0</y_velocity_p_gain>
            <max_x_velocity>0.6</max_x_velocity>
            <max_y_velocity>0.6</max_y_velocity>
            <max_yaw_velocity>0.5</max_yaw_velocity>
        </plugin>
    </gazebo> -->

    <gazebo>
        <plugin name="test" filename="libgazebo_ros_planar_move.so">
            <commandTopic>cmd_vel</commandTopic>
            <odometryTopic>odom</odometryTopic>
            <odometryFrame>odom</odometryFrame>
            <odometryRate>50.0</odometryRate>
            <robotBaseFrame>base_footprint</robotBaseFrame>
        </plugin>
    </gazebo>

    <gazebo reference="front_left_wheel">
        <mu1>0.1</mu1>
        <mu2>0.1</mu2>
        <fdir1>1 1 0</fdir1>
        <material>Gazebo/FlatBlack</material>
    </gazebo>

    <gazebo reference="front_right_wheel">
        <mu1>0.1</mu1>
        <mu2>0.1</mu2>
        <fdir1>1 1 0</fdir1>
        <material>Gazebo/FlatBlack</material>
    </gazebo>

    <gazebo refernece="back_left_wheel">
        <mu1>0.1</mu1>
        <mu2>0.1</mu2>
        <fdir1>1 1 0</fdir1>
        <material>Gazebo/FlatBlack</material>
    </gazebo>

    <gazebo reference="back_right_wheel">
        <mu1>0.1</mu1>
        <mu2>0.1</mu2>
        <fdir1>1 1 0</fdir1>
        <material>Gazebo/FlatBlack</material>
    </gazebo>

    <gazebo reference="imu_link">
        <sensor type="imu" name="imu">
            <always_on>true</always_on>
            <visualize>false</visualize>
            <plugin filename="libgazebo_ros_imu_sensor.so" name="imu_plugin">
                <alwaysOn>true</alwaysOn>
                <topicName>imu</topicName>
                <bodyName>imu_link</bodyName>
                <frameName>imu_link</frameName>
                <!-- <serviceName>imu_service</serviceName> -->
                <updateRateHZ>50.0</updateRateHZ>
                <gaussianNoise>0.0</gaussianNoise>
                <imu>
                    <noise>
                        <type>gaussian</type>
                        <rate>
                            <mean>0.0</mean>
                            <stddev>2e-4</stddev>
                            <bias_mean>0.0000075</bias_mean>
                            <bias_stddev>0.0000008</bias_stddev>
                        </rate>
                        <accel>
                            <mean>0.0</mean>
                            <stddev>1.7e-2</stddev>
                            <bias_mean>0.1</bias_mean>
                            <bias_stddev>0.001</bias_stddev>
                        </accel>
                    </noise>
                </imu>
            </plugin>
        </sensor>
        <material>Gazebo/FlatBlack</material>
    </gazebo>

    <gazebo reference="rplidar_l">
        <sensor type="ray" name="rplidar_l">
            <pose>0 0 0 0 0 0</pose>
            <visualize>true</visualize>
            <update_rate>10</update_rate>
            <ray>
                <scan>
                    <horizontal>
                        <samples>360</samples>
                        <resolution>1</resolution>
                        <min_angle>1.5707</min_angle>
                        <max_angle>6.2830</max_angle>
                    </horizontal>
                </scan>
                <range>
                    <min>0.1</min>
                    <max>40.0</max>
                    <resolution>0.03</resolution>
                </range>
                <noise>
                    <type>gaussian</type>
                    <mean>0.0</mean>
                    <stddev>0.01</stddev>
                </noise>
            </ray>
            <plugin name="rplidar_l" filename="libgazebo_ros_laser.so">
                <topicName>/scan_1</topicName>
                <frameName>rplidar_l</frameName>
            </plugin>
        </sensor>
    </gazebo>

    <gazebo reference="rplidar_r">
        <sensor type="ray" name="rplidar_r">
            <pose>0 0 0 0 0 0</pose>
            <visualize>true</visualize>
            <update_rate>10</update_rate>
            <ray>
                <scan>
                    <horizontal>
                        <samples>360</samples>
                        <resolution>1</resolution>
                        <min_angle>1.5707</min_angle>
                        <max_angle>6.2830</max_angle>
                    </horizontal>
                </scan>
                <range>
                    <min>0.1</min>
                    <max>40.0</max>
                    <resolution>0.03</resolution>
                </range>
                <noise>
                    <type>gaussian</type>
                    <mean>0.0</mean>
                    <stddev>0.01</stddev>
                </noise>
            </ray>
            <plugin name="rplidar_r" filename="libgazebo_ros_laser.so">
                <topicName>/scan_2</topicName>
                <frameName>rplidar_r</frameName>
            </plugin>
        </sensor>
    </gazebo>
    
</robot>